Workbook

Sheet Executive Summary
A1: EXECUTIVE SUMMARY - ITALIAN CORNER
A3: IL CONCEPT IN BREVE
A4: Modello di Business | B4: Catena di corner take-away per piatti pronti italiani di alta qualità, pronti in 60 secondi.
A5: Unique Selling Proposition | B5: Tecnologia di conservazione a 12 mesi senza catena del freddo. Qualità ristorante, velocità fast-food.
A6: Mercato Target | B6: Lavoratori (pranzo veloce), turisti (pasto tipico italiano), clienti salutisti (piatti bilanciati).
A8: METRICHE CHIAVE - SINGOLO PUNTO VENDITA (A REGIME)
A9: Investimento Iniziale per Punto Vendita | B9: ='Investimento & ROI'!B16 | C9: CAPEX completo per apertura.
A10: Fatturato Mensile (100% capacità) | B10: ='P&L Mensile'!D11 | C10: Dopo 10 mesi di ramp-up.
A11: EBITDA Mensile (a regime) | B11: ='P&L Mensile'!D32 | C11: Margine operativo ricorrente.
A12: Margine EBITDA % | B12: ='P&L Mensile'!E32 | C12: Redditività operativa.
A13: Payback Period (singolo Punto Vendita) | B13: ='Investimento & ROI'!B21 | C13: Rientro investimento.
A14: ROI Anno 1 (singolo Punto Vendita) | B14: ='Investimento & ROI'!B22 | C14: Ritorno primo anno.
A16: PIANO DI ESPANSIONE 24 MESI (5 PUNTI VENDITA)
A17: Strategia | B17: Apertura sequenziale per autofinanziare l'espansione con cash flow dei primi PdV.
A18: Timeline Aperture | B18: Punto Vendita 1 (Mese 1) → Punto Vendita 2 (Mese 13) → Punto Vendita 3-5 (ogni 2 mesi).
A19: Modello Ramp-Up | B19: 30% capacità primi 2 mesi, 60% mesi 3-9, 100% da mese 10 in poi.
A21: ANALISI FABBISOGNO FINANZIARIO (ESPANSIONE 5 Punti Vendita)
A22: Investimento Totale Teorico | B22: ='Cash Flow 24 Mesi Multi-Store'!B57 | C22: 5 Punto Vendita × €190.000 (se aperti simultaneamente).
A23: Punto di Minimo CF Cumulativo | B23: ='Cash Flow 24 Mesi Multi-Store'!B58 | C23: Massimo scoperto necessario.
A24: INVESTIMENTO INIZIALE REALE | B24: ='Cash Flow 24 Mesi Multi-Store'!B59 | C24: Capitale effettivamente necessario all'inizio.
A25: Risparmio vs Investimento Teorico | B25: ='Cash Flow 24 Mesi Multi-Store'!B60 | C25: Grazie al cash flow sequenziale.
A26: % Risparmio | B26: ='Cash Flow 24 Mesi Multi-Store'!C60 | C26: Riduzione fabbisogno capitale.
A28: RICHIESTA FINANZIARIA
A29: Importo Richiesto (SEED) | B29: ='Cash Flow 24 Mesi Multi-Store'!B59 | C29: Basato sull'analisi cash flow 24 mesi.
A30: Utilizzo dei Fondi | B30: Apertura sequenziale 5 Punto Vendita nei primi 24 mesi + capitale circolante.
A31: Milestone di Validazione | B31: Break-even previsto entro Mese 20-22. Ricavi consolidati crescenti da Mese 13.

Sheet Parametri
A1: CRUSCOTTO PARAMETRI DEL MODELLO
A2: VOLUMI DI VENDITA (MEDIA GIORNALIERA)
A3: Descrizione | B3: Valore Base | C3: Unità | D3: Pessimistico | E3: Ottimistico
A4: Piatti venduti in store | B4: 250 | C4: pz/giorno | D4: 200 | E4: 400
A5: Piatti venduti in delivery | B5: 120 | C5: pz/giorno | D5: 80 | E5: 180
A6: Bevande (bibite) | B6: 150 | C6: pz/giorno | D6: 100 | E6: 220
A7: Bevande (acqua) | B7: 250 | C7: pz/giorno | D7: 180 | E7: 320
A9: PREZZI DI VENDITA E COSTI VARIABILI (PER UNITÀ)
A10: Descrizione | B10: Prezzo IVA Incl. (€) - INPUT | C10: Prezzo IVA Escl. (€) - CALCOLATO | D10: Costo Unità (€) | E10: % Margine
A11: Piatto pronto | B11: 8 | C11: =B11/(1+$B$35) | D11: 3.5 | E11: =IFERROR((C11-D11)/C11,0)
A12: Bevanda (bibita) | B12: 2.5 | C12: =B12/(1+$B$35) | D12: 0.6 | E12: =IFERROR((C12-D12)/C12,0)
A13: Bevanda (acqua) | B13: 1 | C13: =B13/(1+$B$35) | D13: 0.15 | E13: =IFERROR((C13-D13)/C13,0)
A15: COSTI OPERATIVI (OPEX MENSILI)
A16: Descrizione | B16: Importo Mensile (€) | C16: Note
A17: Affitto locale | B17: 3000 | C17: Locale 25mq in zona strategica
A18: Personale (costo azienda) | B18: =B20*B19 | C18: Calcolato: addetti x costo per addetto
A19: Numero addetti | B19: 2 | C19: Turni per coprire 10-12 ore
A20: Costo lordo per addetto | B20: 3400 | C20: Include stipendio, tasse, contributi
A21: Trasporti e logistica | B21: 800 | C21: Consegna giornaliera materie prime
A22: Utenze (energia, acqua, web) | B22: 700 | C22: Consumo intensivo microonde
A23: Marketing e pubblicità | B23: 1500 | C23: Campagne social, local marketing
A24: Assicurazioni e varie | B24: 500 | C24: RC, commercialista, etc.
A26: PARAMETRI GENERALI
A27: Descrizione | B27: Valore | C27: Unità
A28: Giorni lavorativi al mese | B28: 30 | C28: giorni
A29: Commissione delivery | B29: 0.28 | C29: % sul prezzo
A31: Altri ricavi mensili | B31: 0 | C31: €
A32: Sconti su ricavi (%) | B32: 0 | C32: % sul ricavo
A33: GARANZIE DI LOCAZIONE
A34: Descrizione | B34: Valore | C34: Unità/Note
A35: IVA | B35: 0.1 | C35: € annui
A36: Mensilità richieste a Garanzia | B36: 12 | C36: mesi
A37: Importo da Garantire | B37: =Parametri!B17*B36 | C37: €
A38: Costo % Annuo Fideiussione | B38: 0.015 | C38: % annuo

Sheet P&L Mensile
A1: PROFIT & LOSS MENSILE CON RAMP-UP (COLLEGATO AI PARAMETRI)
A3: Voce | B3: Mese 1 | C3: Mese 2 | D3: Mese 3 | E3: Mese 4 | F3: Mese 5 | G3: Mese 6 | H3: Mese 7 | I3: Mese 8 | J3: Mese 9 | K3: Mese 10 | L3: Mese 11 | M3: Mese 12
A4: RICAVI
A5: Piatti pronti (in store) | B5: =Parametri!B4*Parametri!B28*Parametri!C11*0.3 | C5: =Parametri!B4*Parametri!B28*Parametri!C11*0.3 | D5: =Parametri!B4*Parametri!B28*Parametri!C11*0.6 | E5: =Parametri!B4*Parametri!B28*Parametri!C11*0.6 | F5: =Parametri!B4*Parametri!B28*Parametri!C11*0.6 | G5: =Parametri!B4*Parametri!B28*Parametri!C11*0.6 | H5: =Parametri!B4*Parametri!B28*Parametri!C11*0.6 | I5: =Parametri!B4*Parametri!B28*Parametri!C11*0.6 | J5: =Parametri!B4*Parametri!B28*Parametri!C11*0.6 | K5: =Parametri!B4*Parametri!B28*Parametri!C11*1.0 | L5: =Parametri!B4*Parametri!B28*Parametri!C11*1.0 | M5: =Parametri!B4*Parametri!B28*Parametri!C11*1.0
A6: Piatti pronti (delivery) | B6: =Parametri!B5*Parametri!B28*Parametri!C11*0.3 | C6: =Parametri!B5*Parametri!B28*Parametri!C11*0.3 | D6: =Parametri!B5*Parametri!B28*Parametri!C11*0.6 | E6: =Parametri!B5*Parametri!B28*Parametri!C11*0.6 | F6: =Parametri!B5*Parametri!B28*Parametri!C11*0.6 | G6: =Parametri!B5*Parametri!B28*Parametri!C11*0.6 | H6: =Parametri!B5*Parametri!B28*Parametri!C11*0.6 | I6: =Parametri!B5*Parametri!B28*Parametri!C11*0.6 | J6: =Parametri!B5*Parametri!B28*Parametri!C11*0.6 | K6: =Parametri!B5*Parametri!B28*Parametri!C11*1.0 | L6: =Parametri!B5*Parametri!B28*Parametri!C11*1.0 | M6: =Parametri!B5*Parametri!B28*Parametri!C11*1.0
A7: Bevande (bibite) | B7: =Parametri!B6*Parametri!B28*Parametri!C12*0.3 | C7: =Parametri!B6*Parametri!B28*Parametri!C12*0.3 | D7: =Parametri!B6*Parametri!B28*Parametri!C12*0.6 | E7: =Parametri!B6*Parametri!B28*Parametri!C12*0.6 | F7: =Parametri!B6*Parametri!B28*Parametri!C12*0.6 | G7: =Parametri!B6*Parametri!B28*Parametri!C12*0.6 | H7: =Parametri!B6*Parametri!B28*Parametri!C12*0.6 | I7: =Parametri!B6*Parametri!B28*Parametri!C12*0.6 | J7: =Parametri!B6*Parametri!B28*Parametri!C12*0.6 | K7: =Parametri!B6*Parametri!B28*Parametri!C12*1.0 | L7: =Parametri!B6*Parametri!B28*Parametri!C12*1.0 | M7: =Parametri!B6*Parametri!B28*Parametri!C12*1.0
A8: Bevande (acqua) | B8: =Parametri!B7*Parametri!B28*Parametri!C13*0.3 | C8: =Parametri!B7*Parametri!B28*Parametri!C13*0.3 | D8: =Parametri!B7*Parametri!B28*Parametri!C13*0.6 | E8: =Parametri!B7*Parametri!B28*Parametri!C13*0.6 | F8: =Parametri!B7*Parametri!B28*Parametri!C13*0.6 | G8: =Parametri!B7*Parametri!B28*Parametri!C13*0.6 | H8: =Parametri!B7*Parametri!B28*Parametri!C13*0.6 | I8: =Parametri!B7*Parametri!B28*Parametri!C13*0.6 | J8: =Parametri!B7*Parametri!B28*Parametri!C13*0.6 | K8: =Parametri!B7*Parametri!B28*Parametri!C13*1.0 | L8: =Parametri!B7*Parametri!B28*Parametri!C13*1.0 | M8: =Parametri!B7*Parametri!B28*Parametri!C13*1.0
A9: Altri ricavi | B9: =Parametri!B31 | C9: =Parametri!B31 | D9: =Parametri!B31 | E9: =Parametri!B31 | F9: =Parametri!B31 | G9: =Parametri!B31 | H9: =Parametri!B31 | I9: =Parametri!B31 | J9: =Parametri!B31 | K9: =Parametri!B31 | L9: =Parametri!B31 | M9: =Parametri!B31
A10: Sconti su ricavi | B10: =-SUM(B5:B9)*Parametri!B32 | C10: =-SUM(C5:C9)*Parametri!B32 | D10: =-SUM(D5:D9)*Parametri!B32 | E10: =-SUM(E5:E9)*Parametri!B32 | F10: =-SUM(F5:F9)*Parametri!B32 | G10: =-SUM(G5:G9)*Parametri!B32 | H10: =-SUM(H5:H9)*Parametri!B32 | I10: =-SUM(I5:I9)*Parametri!B32 | J10: =-SUM(J5:J9)*Parametri!B32 | K10: =-SUM(K5:K9)*Parametri!B32 | L10: =-SUM(L5:L9)*Parametri!B32 | M10: =-SUM(M5:M9)*Parametri!B32
A11: Ricavi Totali | B11: =SUM(B5:B10) | C11: =SUM(C5:C10) | D11: =SUM(D5:D10) | E11: =SUM(E5:E10) | F11: =SUM(F5:F10) | G11: =SUM(G5:G10) | H11: =SUM(H5:H10) | I11: =SUM(I5:I10) | ... M11: =SUM(M5:M10)
A13: COSTI VARIABILI (COGS)
A14: Costo piatti pronti | B14: =(Parametri!B4+Parametri!B5)*Parametri!B28*Parametri!D11*0.3 | C14: =(Parametri!B4+Parametri!B5)*Parametri!B28*Parametri!D11*0.3 | D14: =(Parametri!B4+Parametri!B5)*Parametri!B28*Parametri!D11*0.6 | E14: =(Parametri!B4+Parametri!B5)*Parametri!B28*Parametri!D11*0.6 | F14: =(Parametri!B4+Parametri!B5)*Parametri!B28*Parametri!D11*0.6 | G14: =(Parametri!B4+Parametri!B5)*Parametri!B28*Parametri!D11*0.6 | H14: =(Parametri!B4+Parametri!B5)*Parametri!B28*Parametri!D11*0.6 | I14: =(Parametri!B4+Parametri!B5)*Parametri!B28*Parametri!D11*0.6 | J14: =(Parametri!B4+Parametri!B5)*Parametri!B28*Parametri!D11*0.6 | K14: =(Parametri!B4+Parametri!B5)*Parametri!B28*Parametri!D11*1.0 | L14: =(Parametri!B4+Parametri!B5)*Parametri!B28*Parametri!D11*1.0 | M14: =(Parametri!B4+Parametri!B5)*Parametri!B28*Parametri!D11*1.0
A15: Costo bevande (bibite) | B15: =Parametri!B6*Parametri!B28*Parametri!D12*0.3 | C15: =Parametri!B6*Parametri!B28*Parametri!D12*0.3 | D15: =Parametri!B6*Parametri!B28*Parametri!D12*0.6 | E15: =Parametri!B6*Parametri!B28*Parametri!D12*0.6 | F15: =Parametri!B6*Parametri!B28*Parametri!D12*0.6 | G15: =Parametri!B6*Parametri!B28*Parametri!D12*0.6 | H15: =Parametri!B6*Parametri!B28*Parametri!D12*0.6 | I15: =Parametri!B6*Parametri!B28*Parametri!D12*0.6 | J15: =Parametri!B6*Parametri!B28*Parametri!D12*0.6 | K15: =Parametri!B6*Parametri!B28*Parametri!D12*1.0 | L15: =Parametri!B6*Parametri!B28*Parametri!D12*1.0 | M15: =Parametri!B6*Parametri!B28*Parametri!D12*1.0
A16: Costo bevande (acqua) | B16: =Parametri!B7*Parametri!B28*Parametri!D13*0.3 | C16: =Parametri!B7*Parametri!B28*Parametri!D13*0.3 | D16: =Parametri!B7*Parametri!B28*Parametri!D13*0.6 | E16: =Parametri!B7*Parametri!B28*Parametri!D13*0.6 | F16: =Parametri!B7*Parametri!B28*Parametri!D13*0.6 | G16: =Parametri!B7*Parametri!B28*Parametri!D13*0.6 | H16: =Parametri!B7*Parametri!B28*Parametri!D13*0.6 | I16: =Parametri!B7*Parametri!B28*Parametri!D13*0.6 | J16: =Parametri!B7*Parametri!B28*Parametri!D13*0.6 | K16: =Parametri!B7*Parametri!B28*Parametri!D13*1.0 | L16: =Parametri!B7*Parametri!B28*Parametri!D13*1.0 | M16: =Parametri!B7*Parametri!B28*Parametri!D13*1.0
A17: Costi Variabili Totali (COGS) | B17: =SUM(B14:B16) | C17: =SUM(C14:C16) | D17: =SUM(D14:D16) | E17: =SUM(E14:E16) | F17: =SUM(F14:F16) | G17: =SUM(G14:G16) | H17: =SUM(H14:H16) | I17: =SUM(I14:I16) | ... M17: =SUM(M14:M16)
A19: Margine di Contribuzione (Gross Margin) | B19: =B11-B17 | C19: =C11-C17 | D19: =D11-D17 | E19: =E11-E17 | F19: =F11-F17 | G19: =G11-G17 | H19: =H11-H17 | I19: =I11-I17 | ... M19: =M11-M17
A21: COSTI OPERATIVI (OPEX)
A22: Affitto locale | B22: =Parametri!B17 | C22: =Parametri!B17 | D22: =Parametri!B17 | E22: =Parametri!B17 | F22: =Parametri!B17 | G22: =Parametri!B17 | H22: =Parametri!B17 | I22: =Parametri!B17 | J22: =Parametri!B17 | K22: =Parametri!B17 | L22: =Parametri!B17 | M22: =Parametri!B17
A23: Costo Personale | B23: =Parametri!B18 | C23: =Parametri!B18 | D23: =Parametri!B18 | E23: =Parametri!B18 | F23: =Parametri!B18 | G23: =Parametri!B18 | H23: =Parametri!B18 | I23: =Parametri!B18 | J23: =Parametri!B18 | K23: =Parametri!B18 | L23: =Parametri!B18 | M23: =Parametri!B18
A24: Trasporti e logistica | B24: =Parametri!B21 | C24: =Parametri!B21 | D24: =Parametri!B21 | E24: =Parametri!B21 | F24: =Parametri!B21 | G24: =Parametri!B21 | H24: =Parametri!B21 | I24: =Parametri!B21 | J24: =Parametri!B21 | K24: =Parametri!B21 | L24: =Parametri!B21 | M24: =Parametri!B21
A25: Utenze | B25: =Parametri!B22 | C25: =Parametri!B22 | D25: =Parametri!B22 | E25: =Parametri!B22 | F25: =Parametri!B22 | G25: =Parametri!B22 | H25: =Parametri!B22 | I25: =Parametri!B22 | J25: =Parametri!B22 | K25: =Parametri!B22 | L25: =Parametri!B22 | M25: =Parametri!B22
A26: Marketing e pubblicità | B26: =Parametri!B23 | C26: =Parametri!B23 | D26: =Parametri!B23 | E26: =Parametri!B23 | F26: =Parametri!B23 | G26: =Parametri!B23 | H26: =Parametri!B23 | I26: =Parametri!B23 | J26: =Parametri!B23 | K26: =Parametri!B23 | L26: =Parametri!B23 | M26: =Parametri!B23
A27: Commissioni delivery | B27: =B6*Parametri!B29 | C27: =C6*Parametri!B29 | D27: =D6*Parametri!B29 | E27: =E6*Parametri!B29 | F27: =F6*Parametri!B29 | G27: =G6*Parametri!B29 | H27: =H6*Parametri!B29 | I27: =I6*Parametri!B29 | J27: =J6*Parametri!B29 | K27: =K6*Parametri!B29 | L27: =L6*Parametri!B29 | M27: =M6*Parametri!B29
A28: Costo Fideiussione Mensile | B28: =(Parametri!B37*Parametri!B38)/12 | C28: =(Parametri!B37*Parametri!B38)/12 | D28: =(Parametri!B37*Parametri!B38)/12 | E28: =(Parametri!B37*Parametri!B38)/12 | F28: =(Parametri!B37*Parametri!B38)/12 | G28: =(Parametri!B37*Parametri!B38)/12 | H28: =(Parametri!B37*Parametri!B38)/12 | I28: =(Parametri!B37*Parametri!B38)/12 | J28: =(Parametri!B37*Parametri!B38)/12 | K28: =(Parametri!B37*Parametri!B38)/12 | L28: =(Parametri!B37*Parametri!B38)/12 | M28: =(Parametri!B37*Parametri!B38)/12
A29: Assicurazioni e varie | B29: =Parametri!B25 | C29: =Parametri!B25 | D29: =Parametri!B25 | E29: =Parametri!B25 | F29: =Parametri!B25 | G29: =Parametri!B25 | H29: =Parametri!B25 | I29: =Parametri!B25 | J29: =Parametri!B25 | K29: =Parametri!B25 | L29: =Parametri!B25 | M29: =Parametri!B25
A30: Costi Operativi Totali (OPEX) | B30: =SUM(B22:B29) | C30: =SUM(C22:C29) | D30: =SUM(D22:D29) | E30: =SUM(E22:E29) | F30: =SUM(F22:F29) | G30: =SUM(G22:G29) | H30: =SUM(H22:H29) | I30: =SUM(I22:I29) | ... M30: =SUM(M22:M29)
A32: EBITDA (Margine Operativo Lordo) | B32: =B19-B30 | C32: =C19-C30 | D32: =D19-D30 | E32: =E19-E30 | F32: =F19-F30 | G32: =G19-G30 | H32: =H19-H30 | I32: =I19-I30 | ... M32: =M19-M30

Sheet Investimento & ROI
A1: ANALISI INVESTIMENTO INIZIALE E RITORNO
A3: COSTI DI STARTUP (CAPEX) | B3: Importo (€) | C3: % sul Totale | D3: Note
A4: Allestimento e ristrutturazione locale | B4: 25000 | C4: =B4/B12 | D4: Opere murarie, impianti, design (25mq)
A5: Attrezzature cucina (6 microonde, frighi) | B5: 8000 | C5: =B5/B12 | D5: Attrezzatura professionale
A6: Cassa automatica (16335+5360) | B6: 21695 | C6: =B6/B12 | D6: Sistema POS e cassa automatica integrata
A7: Arredi, display e insegne | B7: 10000 | C7: =B7/B12 | D7: Comunicazione in-store e esterna
A8: Costi burocratici e legali | B8: 4000 | C8: =B8/B12 | D8: Licenze, consulenze, apertura società
A9: Budget Marketing di Lancio | B9: 15000 | C9: =B9/B12 | D9: Campagna pre-opening e lancio
A10: Totale CAPEX | B10: =SUM(B4:B9) | C10: =B10/B12
A12: CAPITALE OPERATIVO INIZIALE
A13: Capitale Iniziale (3 Mesi OPEX) | B13: ='P&L Mensile'!M30*3 | C13: =B11/B12 | D13: Cassa per coprire i costi operativi dei primi 3 mesi
A14: INVESTIMENTO TOTALE RICHIESTO | B14: =B10+B11 | C14: =B12/B12 | D14: Fabbisogno finanziario per partire
A16: ANALISI DEL RITORNO SULL'INVESTIMENTO (ROI)
A17: EBITDA Mensile Medio (da P&L) | B17: =AVERAGE('P&L Mensile'!B32:M32) | D17: Margine operativo lordo medio mensile
A18: EBITDA Annuale | B18: =B15*12 | D18: Proiezione a 12 mesi basata sulla media
A19: Payback Period (Mesi) | B19: =IFERROR(B12/B15,0) | D19: Mesi necessari per recuperare l'investimento
A20: ROI a 1 Anno | B20: =IFERROR(B16/B12,0) | D20: (EBITDA Annuale / Investimento Totale)

Sheet Analisi Scenari
A1: ANALISI SCENARI - CONFRONTO BASE / PESSIMISTICO / OTTIMISTICO
A3: Metrica | B3: Scenario Base | C3: Scenario Pessimistico | D3: Scenario Ottimistico | E3: Delta Pess. | F3: Delta Ott. | G3: Sensitività
A4: VOLUMI GIORNALIERI
A5: Piatti in store (pz/gg) | B5: =Parametri!B4 | C5: =Parametri!D4 | D5: =Parametri!E4 | E5: =C5-B5 | F5: =D5-B5 | G5: =IFERROR((D5-C5)/(D5+C5)*2,0)
A6: Piatti delivery (pz/gg) | B6: =Parametri!B5 | C6: =Parametri!D5 | D6: =Parametri!E5 | E6: =C6-B6 | F6: =D6-B6 | G6: =IFERROR((D6-C6)/(D6+C6)*2,0)
A8: PERFORMANCE ECONOMICA MENSILE
A9: Ricavi Totali | B9: =(Parametri!B4*Parametri!B28*Parametri!C11)+(Parametri!B5*Parametri!B28*Parametri!C11)+(Parametri!B6*Parametri!B28*Parametri!C12)+(Parametri!B7*Parametri!B28*Parametri!C13)+Parametri!B31 | C9: =(Parametri!D4*Parametri!B28*Parametri!C11)+(Parametri!D5*Parametri!B28*Parametri!C11)+(Parametri!D6*Parametri!B28*Parametri!C12)+(Parametri!D7*Parametri!B28*Parametri!C13)+Parametri!B31 | D9: =(Parametri!E4*Parametri!B28*Parametri!C11)+(Parametri!E5*Parametri!B28*Parametri!C11)+(Parametri!E6*Parametri!B28*Parametri!C12)+(Parametri!E7*Parametri!B28*Parametri!C13)+Parametri!B31 | E9: =C9-B9 | F9: =D9-B9 | G9: =IFERROR((D9-C9)/B9,0)
A10: COGS Totali | B10: =((Parametri!B4+Parametri!B5)*Parametri!B28*Parametri!D11)+(Parametri!B6*Parametri!B28*Parametri!D12)+(Parametri!B7*Parametri!B28*Parametri!D13) | C10: =((Parametri!D4+Parametri!D5)*Parametri!B28*Parametri!D11)+(Parametri!D6*Parametri!B28*Parametri!D12)+(Parametri!D7*Parametri!B28*Parametri!D13) | D10: =((Parametri!E4+Parametri!E5)*Parametri!B28*Parametri!D11)+(Parametri!E6*Parametri!B28*Parametri!D12)+(Parametri!E7*Parametri!B28*Parametri!D13) | E10: =C10-B10 | F10: =D10-B10 | G10: =IFERROR((D10-C10)/B10,0)
A11: Gross Margin | B11: =B9-B10 | C11: =C9-C10 | D11: =D9-D10 | E11: =C11-B11 | F11: =D11-B11 | G11: =IFERROR((D11-C11)/B11,0)
A12: OPEX Totali | B12: =Parametri!B17+Parametri!B18+Parametri!B21+Parametri!B22+Parametri!B23+Parametri!B24+Parametri!B25+(Parametri!B37*Parametri!B38)/12 | C12: =B12 | D12: =B12 | E12: =C12-B12 | F12: =D12-B12 | G12: =IFERROR((D12-C12)/B12,0)
A13: EBITDA | B13: =B11-B12 | C13: =C11-C12 | D13: =D11-D12 | E13: =C13-B13 | F13: =D13-B13 | G13: =IFERROR((D13-C13)/B13,0)
A14: Margine EBITDA % | B14: =IFERROR(B13/B9,0) | C14: =IFERROR(C13/C9,0) | D14: =IFERROR(D13/D9,0) | E14: =C14-B14 | F14: =D14-B14 | G14: =IFERROR((D14-C14)/B14,0)
A16: RITORNO SULL'INVESTIMENTO
A17: Payback Period (mesi) | B17: =IFERROR('Investimento & ROI'!B15/B13,0) | C17: =IFERROR('Investimento & ROI'!B15/C13,0) | D17: =IFERROR('Investimento & ROI'!B15/D13,0) | E17: =C17-B17 | F17: =D17-B17 | G17: =IFERROR((C17-D17)/B17,0)
A18: ROI Anno 1 (%) | B18: =IFERROR((B13*12)/'Investimento & ROI'!B15,0) | C18: =IFERROR((C13*12)/'Investimento & ROI'!B15,0) | D18: =IFERROR((D13*12)/'Investimento & ROI'!B15,0) | E18: =C18-B18 | F18: =D18-B18 | G18: =IFERROR((D18-C18)/B18,0)
A20: SPIEGAZIONE METRICHE DI INVESTIMENTO
A21: Payback Period (Periodo di Rientro):
A22: Il Payback Period indica quanto tempo (in mesi) è necessario per recuperare completamente l'investimento iniziale attraverso i flussi di cassa generati dall'attività. Si calcola dividendo l'investimento totale per l'EBITDA mensile. Esempio: con un investimento di €166.695 e un EBITDA mensile di €51.530, il payback period è di 3,2 mesi, quindi l'investimento si ripaga in circa 3 mesi.
A24: ROI Anno 1 (Return on Investment):
A25: Il ROI (Return on Investment) misura la redditività dell'investimento in termini percentuali. Si calcola dividendo l'EBITDA annuale (EBITDA mensile × 12) per l'investimento totale. Un ROI del 37,1% significa che il primo anno genererai un ritorno pari al 37,1% dell'investimento iniziale. Esempio: con €166.695 investiti e un EBITDA annuale di €618.360, il ROI è del 371%, indicando un ritorno eccellente sull'investimento.

Sheet Cash Flow 12 Mesi
A1: PROIEZIONE CASH FLOW - 12 MESI
A3: Voce | B3: Mese 1 | C3: Mese 2 | D3: Mese 3 | E3: Mese 4 | F3: Mese 5 | G3: Mese 6 | H3: Mese 7 | I3: Mese 8 | J3: Mese 9 | K3: Mese 10 | L3: Mese 11 | M3: Mese 12
A4: ENTRATE (CASH IN)
A5: Ricavi da vendite | B5: ='P&L Mensile'!B11 | C5: ='P&L Mensile'!C11 | D5: ='P&L Mensile'!D11 | E5: ='P&L Mensile'!E11 | F5: ='P&L Mensile'!F11 | G5: ='P&L Mensile'!G11 | H5: ='P&L Mensile'!H11 | I5: ='P&L Mensile'!I11 | ... M5: ='P&L Mensile'!M11
A6: Totale Entrate | B6: =B5 | C6: =C5 | D6: =D5 | E6: =E5 | F6: =F5 | G6: =G5 | H6: =H5 | I6: =I5 | ... M6: =M5
A8: USCITE (CASH OUT)
A9: Costi variabili (COGS) | B9: ='P&L Mensile'!B17 | C9: ='P&L Mensile'!C17 | D9: ='P&L Mensile'!D17 | E9: ='P&L Mensile'!E17 | F9: ='P&L Mensile'!F17 | G9: ='P&L Mensile'!G17 | H9: ='P&L Mensile'!H17 | I9: ='P&L Mensile'!I17 | ... M9: ='P&L Mensile'!M17
A10: Costi operativi (OPEX) | B10: ='P&L Mensile'!B30 | C10: ='P&L Mensile'!C30 | D10: ='P&L Mensile'!D30 | E10: ='P&L Mensile'!E30 | F10: ='P&L Mensile'!F30 | G10: ='P&L Mensile'!G30 | H10: ='P&L Mensile'!H30 | I10: ='P&L Mensile'!I30 | ... M10: ='P&L Mensile'!M30
A11: Investimento iniziale | B11: ='Investimento & ROI'!B15 | C11: 0 | D11: 0 | E11: 0 | F11: 0 | G11: 0 | H11: 0 | I11: 0 | J11: 0 | K11: 0 | L11: 0 | M11: 0
A12: Totale Uscite | B12: =B9+B10+B11 | C12: =C9+C10+C11 | D12: =D9+D10+D11 | E12: =E9+E10+E11 | F12: =F9+F10+F11 | G12: =G9+G10+G11 | H12: =H9+H10+H11 | I12: =I9+I10+I11 | ... M12: =M9+M10+M11
A14: CASH FLOW ANALYSIS
A15: Cash Flow Mensile | B15: =B6-B12 | C15: =C6-C12 | D15: =D6-D12 | E15: =E6-E12 | F15: =F6-F12 | G15: =G6-G12 | H15: =H6-H12 | I15: =I6-I12 | ... M15: =M6-M12
A16: Cash Flow Cumulativo | B16: =B15 | C16: =B16+C15 | D16: =C16+D15 | E16: =D16+E15 | F16: =E16+F15 | G16: =F16+G15 | H16: =G16+H15 | I16: =H16+I15 | J16: =I16+J15 | ... M16: =L16+M15
A18: Note: | B18: Break-even quando CF Cumulativo > 0

Sheet Cash Flow 24 Mesi Multi-Store
A1: CASH FLOW 24 MESI - ESPANSIONE MULTI-STORE (5 PUNTI VENDITA)
A3: PARAMETRI APERTURE PUNTI VENDITA
A4: Punto Vendita 1 | B4: Mese 1 | C4: ='Investimento & ROI'!B15 | D4: Apertura immediata (anno 1)
A5: Punto Vendita 2 | B5: Mese 13 | C5: ='Investimento & ROI'!B15 | D5: Inizio anno 2
A6: Punto Vendita 3 | B6: Mese 15 | C6: ='Investimento & ROI'!B15 | D6: 2 mesi dopo Punto Vendita 2
A7: Punto Vendita 4 | B7: Mese 17 | C7: ='Investimento & ROI'!B15 | D7: 2 mesi dopo Punto Vendita 3
A8: Punto Vendita 5 | B8: Mese 19 | C8: ='Investimento & ROI'!B15 | D8: 2 mesi dopo Punto Vendita 4
A10: CASH FLOW CONSOLIDATO
A11: Voce | B11: M1 | C11: M2 | D11: M3 | E11: M4 | F11: M5 | G11: M6 | H11: M7 | I11: M8 | J11: M9 | K11: M10 | L11: M11 | M11: M12 | N11: M13 | O11: M14 | P11: M15 | Q11: M16 | R11: M17 | S11: M18 | T11: M19 | U11: M20 | V11: M21 | W11: M22 | X11: M23 | Y11: M24
A12: Investimenti Totali | B12: ='Investimento & ROI'!B15 | C12: 0 | D12: 0 | E12: 0 | F12: 0 | G12: 0 | H12: 0 | I12: 0 | J12: 0 | K12: 0 | L12: 0 | M12: 0 | N12: ='Investimento & ROI'!B15 | O12: 0 | P12: ='Investimento & ROI'!B15 | Q12: 0 | R12: ='Investimento & ROI'!B15 | S12: 0 | T12: ='Investimento & ROI'!B15 | U12: 0 | V12: 0 | W12: 0 | X12: 0 | Y12: 0
A13: Ricavi Totali | B13: =B20+B26+B32+B38+B44 | C13: =C20+C26+C32+C38+C44 | D13: =D20+D26+D32+D38+D44 | E13: =E20+E26+E32+E38+E44 | F13: =F20+F26+F32+F38+F44 | G13: =G20+G26+G32+G38+G44 | H13: =H20+H26+H32+H38+H44 | I13: =I20+I26+I32+I38+I44 | ... Y13: =Y20+Y26+Y32+Y38+Y44
A14: COGS Totali | B14: =B21+B27+B33+B39+B45 | C14: =C21+C27+C33+C39+C45 | D14: =D21+D27+D33+D39+D45 | E14: =E21+E27+E33+E39+E45 | F14: =F21+F27+F33+F39+F45 | G14: =G21+G27+G33+G39+G45 | H14: =H21+H27+H33+H39+H45 | I14: =I21+I27+I33+I39+I45 | ... Y14: =Y21+Y27+Y33+Y39+Y45
A15: OPEX Totali | B15: =B22+B28+B34+B40+B46 | C15: =C22+C28+C34+C40+C46 | D15: =D22+D28+D34+D40+D46 | E15: =E22+E28+E34+E40+E46 | F15: =F22+F28+F34+F40+F46 | G15: =G22+G28+G34+G40+G46 | H15: =H22+H28+H34+H40+H46 | I15: =I22+I28+I34+I40+I46 | ... Y15: =Y22+Y28+Y34+Y40+Y46
A16: Cash Flow Mensile | B16: =B13-B12-B14-B15 | C16: =C13-C12-C14-C15 | D16: =D13-D12-D14-D15 | E16: =E13-E12-E14-E15 | F16: =F13-F12-F14-F15 | G16: =G13-G12-G14-G15 | H16: =H13-H12-H14-H15 | I16: =I13-I12-I14-I15 | ... Y16: =Y13-Y12-Y14-Y15
A17: Cash Flow Cumulativo | B17: =B16 | C17: =B17+C16 | D17: =C17+D16 | E17: =D17+E16 | F17: =E17+F16 | G17: =F17+G16 | H17: =G17+H16 | I17: =H17+I16 | J17: =I17+J16 | ... Y17: =X17+Y16
A19: DETTAGLIO Punto Vendita 1
A20: Ricavi Punto Vendita 1 | B20: ='P&L Mensile'!M11*0.3 | C20: ='P&L Mensile'!M11*0.3 | D20: ='P&L Mensile'!M11*0.6 | E20: ='P&L Mensile'!M11*0.6 | F20: ='P&L Mensile'!M11*0.6 | G20: ='P&L Mensile'!M11*0.6 | H20: ='P&L Mensile'!M11*0.6 | I20: ='P&L Mensile'!M11*0.6 | J20: ='P&L Mensile'!M11*0.6 | K20: ='P&L Mensile'!M11*1.0 | L20: ='P&L Mensile'!M11*1.0 | M20: ='P&L Mensile'!M11*1.0 | N20: ='P&L Mensile'!M11*1.0 | O20: ='P&L Mensile'!M11*1.0 | P20: ='P&L Mensile'!M11*1.0 | Q20: ='P&L Mensile'!M11*1.0 | R20: ='P&L Mensile'!M11*1.0 | S20: ='P&L Mensile'!M11*1.0 | T20: ='P&L Mensile'!M11*1.0 | U20: ='P&L Mensile'!M11*1.0 | V20: ='P&L Mensile'!M11*1.0 | W20: ='P&L Mensile'!M11*1.0 | X20: ='P&L Mensile'!M11*1.0 | Y20: ='P&L Mensile'!M11*1.0
A21: COGS Punto Vendita 1 | B21: ='P&L Mensile'!M17*0.3 | C21: ='P&L Mensile'!M17*0.3 | D21: ='P&L Mensile'!M17*0.6 | E21: ='P&L Mensile'!M17*0.6 | F21: ='P&L Mensile'!M17*0.6 | G21: ='P&L Mensile'!M17*0.6 | H21: ='P&L Mensile'!M17*0.6 | I21: ='P&L Mensile'!M17*0.6 | J21: ='P&L Mensile'!M17*0.6 | K21: ='P&L Mensile'!M17*1.0 | L21: ='P&L Mensile'!M17*1.0 | M21: ='P&L Mensile'!M17*1.0 | N21: ='P&L Mensile'!M17*1.0 | O21: ='P&L Mensile'!M17*1.0 | P21: ='P&L Mensile'!M17*1.0 | Q21: ='P&L Mensile'!M17*1.0 | R21: ='P&L Mensile'!M17*1.0 | S21: ='P&L Mensile'!M17*1.0 | T21: ='P&L Mensile'!M17*1.0 | U21: ='P&L Mensile'!M17*1.0 | V21: ='P&L Mensile'!M17*1.0 | W21: ='P&L Mensile'!M17*1.0 | X21: ='P&L Mensile'!M17*1.0 | Y21: ='P&L Mensile'!M17*1.0
A22: OPEX Punto Vendita 1 | B22: ='P&L Mensile'!M30 | C22: ='P&L Mensile'!M30 | D22: ='P&L Mensile'!M30 | E22: ='P&L Mensile'!M30 | F22: ='P&L Mensile'!M30 | G22: ='P&L Mensile'!M30 | H22: ='P&L Mensile'!M30 | I22: ='P&L Mensile'!M30 | J22: ='P&L Mensile'!M30 | K22: ='P&L Mensile'!M30 | L22: ='P&L Mensile'!M30 | M22: ='P&L Mensile'!M30 | N22: ='P&L Mensile'!M30 | O22: ='P&L Mensile'!M30 | P22: ='P&L Mensile'!M30 | Q22: ='P&L Mensile'!M30 | R22: ='P&L Mensile'!M30 | S22: ='P&L Mensile'!M30 | T22: ='P&L Mensile'!M30 | U22: ='P&L Mensile'!M30 | V22: ='P&L Mensile'!M30 | W22: ='P&L Mensile'!M30 | X22: ='P&L Mensile'!M30 | Y22: ='P&L Mensile'!M30
A23: CF Punto Vendita 1 | B23: =B20-'Investimento & ROI'!B15-B21-B22 | C23: =C20-0-C21-C22 | D23: =D20-0-D21-D22 | E23: =E20-0-E21-E22 | F23: =F20-0-F21-F22 | G23: =G20-0-G21-G22 | H23: =H20-0-H21-H22 | I23: =I20-0-I21-I22 | J23: =J20-0-J21-J22 | ... Y23: =Y20-0-Y21-Y22
A25: DETTAGLIO Punto Vendita 2
A26: Ricavi Punto Vendita 2 | B26: 0 | C26: 0 | D26: 0 | E26: 0 | F26: 0 | G26: 0 | H26: 0 | I26: 0 | J26: 0 | K26: 0 | L26: 0 | M26: 0 | N26: ='P&L Mensile'!M11*0.3 | O26: ='P&L Mensile'!M11*0.3 | P26: ='P&L Mensile'!M11*0.6 | Q26: ='P&L Mensile'!M11*0.6 | R26: ='P&L Mensile'!M11*0.6 | S26: ='P&L Mensile'!M11*0.6 | T26: ='P&L Mensile'!M11*0.6 | U26: ='P&L Mensile'!M11*0.6 | V26: ='P&L Mensile'!M11*0.6 | W26: ='P&L Mensile'!M11*1.0 | X26: ='P&L Mensile'!M11*1.0 | Y26: ='P&L Mensile'!M11*1.0
A27: COGS Punto Vendita 2 | B27: 0 | C27: 0 | D27: 0 | E27: 0 | F27: 0 | G27: 0 | H27: 0 | I27: 0 | J27: 0 | K27: 0 | L27: 0 | M27: 0 | N27: ='P&L Mensile'!M17*0.3 | O27: ='P&L Mensile'!M17*0.3 | P27: ='P&L Mensile'!M17*0.6 | Q27: ='P&L Mensile'!M17*0.6 | R27: ='P&L Mensile'!M17*0.6 | S27: ='P&L Mensile'!M17*0.6 | T27: ='P&L Mensile'!M17*0.6 | U27: ='P&L Mensile'!M17*0.6 | V27: ='P&L Mensile'!M17*0.6 | W27: ='P&L Mensile'!M17*1.0 | X27: ='P&L Mensile'!M17*1.0 | Y27: ='P&L Mensile'!M17*1.0
A28: OPEX Punto Vendita 2 | B28: 0 | C28: 0 | D28: 0 | E28: 0 | F28: 0 | G28: 0 | H28: 0 | I28: 0 | J28: 0 | K28: 0 | L28: 0 | M28: 0 | N28: ='P&L Mensile'!M30 | O28: ='P&L Mensile'!M30 | P28: ='P&L Mensile'!M30 | Q28: ='P&L Mensile'!M30 | R28: ='P&L Mensile'!M30 | S28: ='P&L Mensile'!M30 | T28: ='P&L Mensile'!M30 | U28: ='P&L Mensile'!M30 | V28: ='P&L Mensile'!M30 | W28: ='P&L Mensile'!M30 | X28: ='P&L Mensile'!M30 | Y28: ='P&L Mensile'!M30
A29: CF Punto Vendita 2 | B29: =B26-0-B27-B28 | C29: =C26-0-C27-C28 | D29: =D26-0-D27-D28 | E29: =E26-0-E27-E28 | F29: =F26-0-F27-F28 | G29: =G26-0-G27-G28 | H29: =H26-0-H27-H28 | I29: =I26-0-I27-I28 | ... M29: =M26-0-M27-M28 | N29: =N26-'Investimento & ROI'!B15-N27-N28 | O29: =O26-0-O27-O28 | P29: =P26-0-P27-P28 | Q29: =Q26-0-Q27-Q28 | R29: =R26-0-R27-R28 | S29: =S26-0-S27-S28 | T29: =T26-0-T27-T28 | U29: =U26-0-U27-U28 | V29: =V26-0-V27-V28 | ... Y29: =Y26-0-Y27-Y28
A31: DETTAGLIO Punto Vendita 3
A32: Ricavi Punto Vendita 3 | B32: 0 | C32: 0 | D32: 0 | E32: 0 | F32: 0 | G32: 0 | H32: 0 | I32: 0 | J32: 0 | K32: 0 | L32: 0 | M32: 0 | N32: 0 | O32: 0 | P32: ='P&L Mensile'!M11*0.3 | Q32: ='P&L Mensile'!M11*0.3 | R32: ='P&L Mensile'!M11*0.6 | S32: ='P&L Mensile'!M11*0.6 | T32: ='P&L Mensile'!M11*0.6 | U32: ='P&L Mensile'!M11*0.6 | V32: ='P&L Mensile'!M11*0.6 | W32: ='P&L Mensile'!M11*0.6 | X32: ='P&L Mensile'!M11*0.6 | Y32: ='P&L Mensile'!M11*1.0
A33: COGS Punto Vendita 3 | B33: 0 | C33: 0 | D33: 0 | E33: 0 | F33: 0 | G33: 0 | H33: 0 | I33: 0 | J33: 0 | K33: 0 | L33: 0 | M33: 0 | N33: 0 | O33: 0 | P33: ='P&L Mensile'!M17*0.3 | Q33: ='P&L Mensile'!M17*0.3 | R33: ='P&L Mensile'!M17*0.6 | S33: ='P&L Mensile'!M17*0.6 | T33: ='P&L Mensile'!M17*0.6 | U33: ='P&L Mensile'!M17*0.6 | V33: ='P&L Mensile'!M17*0.6 | W33: ='P&L Mensile'!M17*0.6 | X33: ='P&L Mensile'!M17*0.6 | Y33: ='P&L Mensile'!M17*1.0
A34: OPEX Punto Vendita 3 | B34: 0 | C34: 0 | D34: 0 | E34: 0 | F34: 0 | G34: 0 | H34: 0 | I34: 0 | J34: 0 | K34: 0 | L34: 0 | M34: 0 | N34: 0 | O34: 0 | P34: ='P&L Mensile'!M30 | Q34: ='P&L Mensile'!M30 | R34: ='P&L Mensile'!M30 | S34: ='P&L Mensile'!M30 | T34: ='P&L Mensile'!M30 | U34: ='P&L Mensile'!M30 | V34: ='P&L Mensile'!M30 | W34: ='P&L Mensile'!M30 | X34: ='P&L Mensile'!M30 | Y34: ='P&L Mensile'!M30
A35: CF Punto Vendita 3 | B35: =B32-0-B33-B34 | C35: =C32-0-C33-C34 | D35: =D32-0-D33-D34 | E35: =E32-0-E33-E34 | F35: =F32-0-F33-F34 | G35: =G32-0-G33-G34 | H35: =H32-0-H33-H34 | I35: =I32-0-I33-I34 | ... O35: =O32-0-O33-O34 | P35: =P32-'Investimento & ROI'!B15-P33-P34 | Q35: =Q32-0-Q33-Q34 | R35: =R32-0-R33-R34 | S35: =S32-0-S33-S34 | T35: =T32-0-T33-T34 | U35: =U32-0-U33-U34 | V35: =V32-0-V33-V34 | W35: =W32-0-W33-W34 | X35: =X32-0-X33-X34 | Y35: =Y32-0-Y33-Y34
A37: DETTAGLIO Punto Vendita 4
A38: Ricavi Punto Vendita 4 | B38: 0 | C38: 0 | D38: 0 | E38: 0 | F38: 0 | G38: 0 | H38: 0 | I38: 0 | J38: 0 | K38: 0 | L38: 0 | M38: 0 | N38: 0 | O38: 0 | P38: 0 | Q38: 0 | R38: ='P&L Mensile'!M11*0.3 | S38: ='P&L Mensile'!M11*0.3 | T38: ='P&L Mensile'!M11*0.6 | U38: ='P&L Mensile'!M11*0.6 | V38: ='P&L Mensile'!M11*0.6 | W38: ='P&L Mensile'!M11*0.6 | X38: ='P&L Mensile'!M11*0.6 | Y38: ='P&L Mensile'!M11*0.6
A39: COGS Punto Vendita 4 | B39: 0 | C39: 0 | D39: 0 | E39: 0 | F39: 0 | G39: 0 | H39: 0 | I39: 0 | J39: 0 | K39: 0 | L39: 0 | M39: 0 | N39: 0 | O39: 0 | P39: 0 | Q39: 0 | R39: ='P&L Mensile'!M17*0.3 | S39: ='P&L Mensile'!M17*0.3 | T39: ='P&L Mensile'!M17*0.6 | U39: ='P&L Mensile'!M17*0.6 | V39: ='P&L Mensile'!M17*0.6 | W39: ='P&L Mensile'!M17*0.6 | X39: ='P&L Mensile'!M17*0.6 | Y39: ='P&L Mensile'!M17*0.6
A40: OPEX Punto Vendita 4 | B40: 0 | C40: 0 | D40: 0 | E40: 0 | F40: 0 | G40: 0 | H40: 0 | I40: 0 | J40: 0 | K40: 0 | L40: 0 | M40: 0 | N40: 0 | O40: 0 | P40: 0 | Q40: 0 | R40: ='P&L Mensile'!M30 | S40: ='P&L Mensile'!M30 | T40: ='P&L Mensile'!M30 | U40: ='P&L Mensile'!M30 | V40: ='P&L Mensile'!M30 | W40: ='P&L Mensile'!M30 | X40: ='P&L Mensile'!M30 | Y40: ='P&L Mensile'!M30
A41: CF Punto Vendita 4 | B41: =B38-0-B39-B40 | C41: =C38-0-C39-C40 | D41: =D38-0-D39-D40 | E41: =E38-0-E39-E40 | F41: =F38-0-F39-F40 | G41: =G38-0-G39-G40 | H41: =H38-0-H39-H40 | I41: =I38-0-I39-I40 | ... Q41: =Q38-0-Q39-Q40 | R41: =R38-'Investimento & ROI'!B15-R39-R40 | S41: =S38-0-S39-S40 | T41: =T38-0-T39-T40 | U41: =U38-0-U39-U40 | V41: =V38-0-V39-V40 | W41: =W38-0-W39-W40 | X41: =X38-0-X39-X40 | Y41: =Y38-0-Y39-Y40
A43: DETTAGLIO Punto Vendita 5
A44: Ricavi Punto Vendita 5 | B44: 0 | C44: 0 | D44: 0 | E44: 0 | F44: 0 | G44: 0 | H44: 0 | I44: 0 | J44: 0 | K44: 0 | L44: 0 | M44: 0 | N44: 0 | O44: 0 | P44: 0 | Q44: 0 | R44: 0 | S44: 0 | T44: ='P&L Mensile'!M11*0.3 | U44: ='P&L Mensile'!M11*0.3 | V44: ='P&L Mensile'!M11*0.6 | W44: ='P&L Mensile'!M11*0.6 | X44: ='P&L Mensile'!M11*0.6 | Y44: ='P&L Mensile'!M11*0.6
A45: COGS Punto Vendita 5 | B45: 0 | C45: 0 | D45: 0 | E45: 0 | F45: 0 | G45: 0 | H45: 0 | I45: 0 | J45: 0 | K45: 0 | L45: 0 | M45: 0 | N45: 0 | O45: 0 | P45: 0 | Q45: 0 | R45: 0 | S45: 0 | T45: ='P&L Mensile'!M17*0.3 | U45: ='P&L Mensile'!M17*0.3 | V45: ='P&L Mensile'!M17*0.6 | W45: ='P&L Mensile'!M17*0.6 | X45: ='P&L Mensile'!M17*0.6 | Y45: ='P&L Mensile'!M17*0.6
A46: OPEX Punto Vendita 5 | B46: 0 | C46: 0 | D46: 0 | E46: 0 | F46: 0 | G46: 0 | H46: 0 | I46: 0 | J46: 0 | K46: 0 | L46: 0 | M46: 0 | N46: 0 | O46: 0 | P46: 0 | Q46: 0 | R46: 0 | S46: 0 | T46: ='P&L Mensile'!M30 | U46: ='P&L Mensile'!M30 | V46: ='P&L Mensile'!M30 | W46: ='P&L Mensile'!M30 | X46: ='P&L Mensile'!M30 | Y46: ='P&L Mensile'!M30
A47: CF Punto Vendita 5 | B47: =B44-0-B45-B46 | C47: =C44-0-C45-C46 | D47: =D44-0-D45-D46 | E47: =E44-0-E45-E46 | F47: =F44-0-F45-F46 | G47: =G44-0-G45-G46 | H47: =H44-0-H45-H46 | I47: =I44-0-I45-I46 | ... S47: =S44-0-S45-S46 | T47: =T44-'Investimento & ROI'!B15-T45-T46 | U47: =U44-0-U45-U46 | V47: =V44-0-V45-V46 | W47: =W44-0-W45-W46 | X47: =X44-0-X45-X46 | Y47: =Y44-0-Y45-Y46
...
